<?xml version="1.0" ?>
<!-- =================================================================================== -->
<!-- |    This document was autogenerated by xacro from /home/oli/src/Firmware/Tools/sitl_gazebo/models/rotors_description/urdf/iris_camera_tag.xacro | -->
<!-- |    EDITING THIS FILE BY HAND IS NOT RECOMMENDED                                 | -->
<!-- =================================================================================== -->
<robot name="iris_camera" xmlns:xacro="http://www.ros.org/wiki/xacro">
  <link name="base_link"/>
  <joint name="base_joint" type="fixed">
    <origin rpy="0 0 0" xyz="0 0 0"/>
    <parent link="base_link"/>
    <child link="base_link_inertia"/>
  </joint>
  <link name="base_link_inertia">
    <inertial>
      <mass value="1.5"/>
      <!-- [kg] -->
      <origin xyz="0 0 0"/>
      <inertia ixx="0.0347563" ixy="0.0" ixz="0.0" iyy="0.0458929" iyz="0.0" izz="0.0977"/>
    </inertial>
    <visual>
      <origin rpy="0 0 0" xyz="0 0 0"/>
      <geometry>
        <mesh filename="/home/oli/src/Firmware/Tools/sitl_gazebo/models/rotors_description/meshes/iris.stl" scale="1 1 1"/>
        <!-- <box size="${body_width} ${body_width} ${body_height}"/> -->
        <!-- [m] [m] [m] -->
      </geometry>
    </visual>
    <collision>
      <origin rpy="0 0 0" xyz="0 0 0"/>
      <geometry>
        <box size="0.47 0.47 0.11"/>
        <!-- [m] [m] [m] -->
      </geometry>
    </collision>
  </link>
  <!-- attach multirotor_base_plugin to the base_link -->
  <gazebo>
    <plugin filename="librotors_gazebo_multirotor_base_plugin.so" name="rosbag">
      <robotNamespace></robotNamespace>
      <linkName>base_link</linkName>
      <rotorVelocitySlowdownSim>10</rotorVelocitySlowdownSim>
    </plugin>
  </gazebo>
  <gazebo reference="base_link">
    <material>Gazebo/DarkGrey</material>
    <collision name="base_link_inertia_collision">
      <surface>
        <contact>
          <ode>
            <min_depth>0.001</min_depth>
            <max_vel>0.0</max_vel>
          </ode>
        </contact>
        <friction>
          <ode/>
        </friction>
      </surface>
    </collision>
  </gazebo>
  <joint name="rotor_0_joint" type="continuous">
    <origin rpy="0 0 0" xyz="0.13 -0.22 0.023"/>
    <axis xyz="0 0 1"/>
    <!-- TODO(ff): not currently set because it's not yet supported -->
    <!-- <limit effort="2000" velocity="${max_rot_velocity}" /> -->
    <parent link="base_link"/>
    <child link="rotor_0"/>
  </joint>
  <!-- TODO(ff): not currently set because it's not yet supported -->
  <!-- <gazebo reference="rotor_${motor_number}_joint"> <axis> <xyz>0 0 1</xyz>
      <limit> <velocity> ${max_rot_velocity} </velocity> </limit> </axis> </gazebo> -->
  <link name="rotor_0">
    <inertial>
      <mass value="0.005"/>
      <!-- [kg] -->
      <inertia ixx="9.75e-07" ixy="0.0" ixz="0.0" iyy="0.000273104166667" iyz="0.0" izz="0.000274004166667"/>
    </inertial>
    <visual>
      <geometry>
        <!-- <cylinder length="0.005" radius="${radius_rotor}"/> -->
        <!-- [m] -->
        <!-- <mesh filename="/home/oli/src/Firmware/Tools/sitl_gazebo/models/rotors_description/meshes/propeller_${direction}.dae" -->
        <mesh filename="/home/oli/src/Firmware/Tools/sitl_gazebo/models/rotors_description/meshes/iris_prop_ccw.dae" scale="1 1 1"/>
        <!-- <box size="${2*radius_rotor} 0.01 0.005"/> -->
      </geometry>
    </visual>
    <collision>
      <geometry>
        <cylinder length="0.005" radius="0.128"/>
        <!-- [m] -->
      </geometry>
    </collision>
  </link>
  <gazebo>
    <plugin filename="librotors_gazebo_motor_model.so" name="front_right_motor_model">
      <robotNamespace></robotNamespace>
      <jointName>rotor_0_joint</jointName>
      <linkName>rotor_0</linkName>
      <turningDirection>ccw</turningDirection>
      <timeConstantUp>0.0125</timeConstantUp>
      <timeConstantDown>0.025</timeConstantDown>
      <maxRotVelocity>1100</maxRotVelocity>
      <motorConstant>8.54858e-06</motorConstant>
      <momentConstant>0.06</momentConstant>
      <commandSubTopic>/gazebo/command/motor_speed</commandSubTopic>
      <motorNumber>0</motorNumber>
      <rotorDragCoefficient>0.000806428</rotorDragCoefficient>
      <rollingMomentCoefficient>1e-06</rollingMomentCoefficient>
      <motorSpeedPubTopic>/motor_speed/0</motorSpeedPubTopic>
      <rotorVelocitySlowdownSim>10</rotorVelocitySlowdownSim>
      <!--
        <gazebo_joint_control_pid>
          <p>0.1</p>
          <i>0</i>
          <d>0</d>
          <iMax>0</iMax>
          <iMin>0</iMin>
          <cmdMax>3</cmdMax>
          <cmdMin>-3</cmdMin>
        </gazebo_joint_control_pid>
      -->
    </plugin>
  </gazebo>
  <gazebo reference="rotor_0">
    <material>Gazebo/Blue</material>
  </gazebo>
  <joint name="rotor_1_joint" type="continuous">
    <origin rpy="0 0 0" xyz="-0.13 0.2 0.023"/>
    <axis xyz="0 0 1"/>
    <!-- TODO(ff): not currently set because it's not yet supported -->
    <!-- <limit effort="2000" velocity="${max_rot_velocity}" /> -->
    <parent link="base_link"/>
    <child link="rotor_1"/>
  </joint>
  <!-- TODO(ff): not currently set because it's not yet supported -->
  <!-- <gazebo reference="rotor_${motor_number}_joint"> <axis> <xyz>0 0 1</xyz>
      <limit> <velocity> ${max_rot_velocity} </velocity> </limit> </axis> </gazebo> -->
  <link name="rotor_1">
    <inertial>
      <mass value="0.005"/>
      <!-- [kg] -->
      <inertia ixx="9.75e-07" ixy="0.0" ixz="0.0" iyy="0.000273104166667" iyz="0.0" izz="0.000274004166667"/>
    </inertial>
    <visual>
      <geometry>
        <!-- <cylinder length="0.005" radius="${radius_rotor}"/> -->
        <!-- [m] -->
        <!-- <mesh filename="/home/oli/src/Firmware/Tools/sitl_gazebo/models/rotors_description/meshes/propeller_${direction}.dae" -->
        <mesh filename="/home/oli/src/Firmware/Tools/sitl_gazebo/models/rotors_description/meshes/iris_prop_ccw.dae" scale="1 1 1"/>
        <!-- <box size="${2*radius_rotor} 0.01 0.005"/> -->
      </geometry>
    </visual>
    <collision>
      <geometry>
        <cylinder length="0.005" radius="0.128"/>
        <!-- [m] -->
      </geometry>
    </collision>
  </link>
  <gazebo>
    <plugin filename="librotors_gazebo_motor_model.so" name="back_left_motor_model">
      <robotNamespace></robotNamespace>
      <jointName>rotor_1_joint</jointName>
      <linkName>rotor_1</linkName>
      <turningDirection>ccw</turningDirection>
      <timeConstantUp>0.0125</timeConstantUp>
      <timeConstantDown>0.025</timeConstantDown>
      <maxRotVelocity>1100</maxRotVelocity>
      <motorConstant>8.54858e-06</motorConstant>
      <momentConstant>0.06</momentConstant>
      <commandSubTopic>/gazebo/command/motor_speed</commandSubTopic>
      <motorNumber>1</motorNumber>
      <rotorDragCoefficient>0.000806428</rotorDragCoefficient>
      <rollingMomentCoefficient>1e-06</rollingMomentCoefficient>
      <motorSpeedPubTopic>/motor_speed/1</motorSpeedPubTopic>
      <rotorVelocitySlowdownSim>10</rotorVelocitySlowdownSim>
      <!--
        <gazebo_joint_control_pid>
          <p>0.1</p>
          <i>0</i>
          <d>0</d>
          <iMax>0</iMax>
          <iMin>0</iMin>
          <cmdMax>3</cmdMax>
          <cmdMin>-3</cmdMin>
        </gazebo_joint_control_pid>
      -->
    </plugin>
  </gazebo>
  <gazebo reference="rotor_1">
    <material>Gazebo/DarkGrey</material>
  </gazebo>
  <joint name="rotor_2_joint" type="continuous">
    <origin rpy="0 0 0" xyz="0.13 0.22 0.023"/>
    <axis xyz="0 0 1"/>
    <!-- TODO(ff): not currently set because it's not yet supported -->
    <!-- <limit effort="2000" velocity="${max_rot_velocity}" /> -->
    <parent link="base_link"/>
    <child link="rotor_2"/>
  </joint>
  <!-- TODO(ff): not currently set because it's not yet supported -->
  <!-- <gazebo reference="rotor_${motor_number}_joint"> <axis> <xyz>0 0 1</xyz>
      <limit> <velocity> ${max_rot_velocity} </velocity> </limit> </axis> </gazebo> -->
  <link name="rotor_2">
    <inertial>
      <mass value="0.005"/>
      <!-- [kg] -->
      <inertia ixx="9.75e-07" ixy="0.0" ixz="0.0" iyy="0.000273104166667" iyz="0.0" izz="0.000274004166667"/>
    </inertial>
    <visual>
      <geometry>
        <!-- <cylinder length="0.005" radius="${radius_rotor}"/> -->
        <!-- [m] -->
        <!-- <mesh filename="/home/oli/src/Firmware/Tools/sitl_gazebo/models/rotors_description/meshes/propeller_${direction}.dae" -->
        <mesh filename="/home/oli/src/Firmware/Tools/sitl_gazebo/models/rotors_description/meshes/iris_prop_cw.dae" scale="1 1 1"/>
        <!-- <box size="${2*radius_rotor} 0.01 0.005"/> -->
      </geometry>
    </visual>
    <collision>
      <geometry>
        <cylinder length="0.005" radius="0.128"/>
        <!-- [m] -->
      </geometry>
    </collision>
  </link>
  <gazebo>
    <plugin filename="librotors_gazebo_motor_model.so" name="front_left_motor_model">
      <robotNamespace></robotNamespace>
      <jointName>rotor_2_joint</jointName>
      <linkName>rotor_2</linkName>
      <turningDirection>cw</turningDirection>
      <timeConstantUp>0.0125</timeConstantUp>
      <timeConstantDown>0.025</timeConstantDown>
      <maxRotVelocity>1100</maxRotVelocity>
      <motorConstant>8.54858e-06</motorConstant>
      <momentConstant>0.06</momentConstant>
      <commandSubTopic>/gazebo/command/motor_speed</commandSubTopic>
      <motorNumber>2</motorNumber>
      <rotorDragCoefficient>0.000806428</rotorDragCoefficient>
      <rollingMomentCoefficient>1e-06</rollingMomentCoefficient>
      <motorSpeedPubTopic>/motor_speed/2</motorSpeedPubTopic>
      <rotorVelocitySlowdownSim>10</rotorVelocitySlowdownSim>
      <!--
        <gazebo_joint_control_pid>
          <p>0.1</p>
          <i>0</i>
          <d>0</d>
          <iMax>0</iMax>
          <iMin>0</iMin>
          <cmdMax>3</cmdMax>
          <cmdMin>-3</cmdMin>
        </gazebo_joint_control_pid>
      -->
    </plugin>
  </gazebo>
  <gazebo reference="rotor_2">
    <material>Gazebo/Blue</material>
  </gazebo>
  <joint name="rotor_3_joint" type="continuous">
    <origin rpy="0 0 0" xyz="-0.13 -0.2 0.023"/>
    <axis xyz="0 0 1"/>
    <!-- TODO(ff): not currently set because it's not yet supported -->
    <!-- <limit effort="2000" velocity="${max_rot_velocity}" /> -->
    <parent link="base_link"/>
    <child link="rotor_3"/>
  </joint>
  <!-- TODO(ff): not currently set because it's not yet supported -->
  <!-- <gazebo reference="rotor_${motor_number}_joint"> <axis> <xyz>0 0 1</xyz>
      <limit> <velocity> ${max_rot_velocity} </velocity> </limit> </axis> </gazebo> -->
  <link name="rotor_3">
    <inertial>
      <mass value="0.005"/>
      <!-- [kg] -->
      <inertia ixx="9.75e-07" ixy="0.0" ixz="0.0" iyy="0.000273104166667" iyz="0.0" izz="0.000274004166667"/>
    </inertial>
    <visual>
      <geometry>
        <!-- <cylinder length="0.005" radius="${radius_rotor}"/> -->
        <!-- [m] -->
        <!-- <mesh filename="/home/oli/src/Firmware/Tools/sitl_gazebo/models/rotors_description/meshes/propeller_${direction}.dae" -->
        <mesh filename="/home/oli/src/Firmware/Tools/sitl_gazebo/models/rotors_description/meshes/iris_prop_cw.dae" scale="1 1 1"/>
        <!-- <box size="${2*radius_rotor} 0.01 0.005"/> -->
      </geometry>
    </visual>
    <collision>
      <geometry>
        <cylinder length="0.005" radius="0.128"/>
        <!-- [m] -->
      </geometry>
    </collision>
  </link>
  <gazebo>
    <plugin filename="librotors_gazebo_motor_model.so" name="back_right_motor_model">
      <robotNamespace></robotNamespace>
      <jointName>rotor_3_joint</jointName>
      <linkName>rotor_3</linkName>
      <turningDirection>cw</turningDirection>
      <timeConstantUp>0.0125</timeConstantUp>
      <timeConstantDown>0.025</timeConstantDown>
      <maxRotVelocity>1100</maxRotVelocity>
      <motorConstant>8.54858e-06</motorConstant>
      <momentConstant>0.06</momentConstant>
      <commandSubTopic>/gazebo/command/motor_speed</commandSubTopic>
      <motorNumber>3</motorNumber>
      <rotorDragCoefficient>0.000806428</rotorDragCoefficient>
      <rollingMomentCoefficient>1e-06</rollingMomentCoefficient>
      <motorSpeedPubTopic>/motor_speed/3</motorSpeedPubTopic>
      <rotorVelocitySlowdownSim>10</rotorVelocitySlowdownSim>
      <!--
        <gazebo_joint_control_pid>
          <p>0.1</p>
          <i>0</i>
          <d>0</d>
          <iMax>0</iMax>
          <iMin>0</iMin>
          <cmdMax>3</cmdMax>
          <cmdMin>-3</cmdMin>
        </gazebo_joint_control_pid>
      -->
    </plugin>
  </gazebo>
  <gazebo reference="rotor_3">
    <material>Gazebo/DarkGrey</material>
  </gazebo>
  <gazebo>
    <plugin filename="librotors_gazebo_mavlink_interface.so" name="mavlink_interface">
      <robotNamespace></robotNamespace>
      <imuSubTopic>/imu</imuSubTopic>
      <mavlink_addr>INADDR_ANY</mavlink_addr>
      <mavlink_udp_port>14560</mavlink_udp_port>
      <motorSpeedCommandPubTopic>/gazebo/command/motor_speed</motorSpeedCommandPubTopic>
      <control_channels>
        <channel name="rotor1">
          <input_index>0</input_index>
          <input_offset>0</input_offset>
          <input_scaling>1000</input_scaling>
          <zero_position_disarmed>0</zero_position_disarmed>
          <zero_position_armed>100</zero_position_armed>
          <joint_control_type>velocity</joint_control_type>
        </channel>
        <channel name="rotor2">
          <input_index>1</input_index>
          <input_offset>0</input_offset>
          <input_scaling>1000</input_scaling>
          <zero_position_disarmed>0</zero_position_disarmed>
          <zero_position_armed>100</zero_position_armed>
          <joint_control_type>velocity</joint_control_type>
        </channel>
        <channel name="rotor3">
          <input_index>2</input_index>
          <input_offset>0</input_offset>
          <input_scaling>1000</input_scaling>
          <zero_position_disarmed>0</zero_position_disarmed>
          <zero_position_armed>100</zero_position_armed>
          <joint_control_type>velocity</joint_control_type>
        </channel>
        <channel name="rotor4">
          <input_index>3</input_index>
          <input_offset>0</input_offset>
          <input_scaling>1000</input_scaling>
          <zero_position_disarmed>0</zero_position_disarmed>
          <zero_position_armed>100</zero_position_armed>
          <joint_control_type>velocity</joint_control_type>
        </channel>
        <channel name="rotor5">
          <input_index>4</input_index>
          <input_offset>1</input_offset>
          <input_scaling>324.6</input_scaling>
          <zero_position_disarmed>0</zero_position_disarmed>
          <zero_position_armed>0</zero_position_armed>
          <joint_control_type>velocity</joint_control_type>
          <joint_control_pid>
            <p>0.1</p>
            <i>0</i>
            <d>0</d>
            <iMax>0.0</iMax>
            <iMin>0.0</iMin>
            <cmdMax>2</cmdMax>
            <cmdMin>-2</cmdMin>
          </joint_control_pid>
          <joint_name>zephyr_delta_wing::propeller_joint</joint_name>
        </channel>
        <channel name="rotor6">
          <input_index>5</input_index>
          <input_offset>0</input_offset>
          <!-- joint limits [-0.524, 0.524] -->
          <input_scaling>0.524</input_scaling>
          <zero_position_disarmed>0</zero_position_disarmed>
          <zero_position_armed>0</zero_position_armed>
          <joint_control_type>position</joint_control_type>
          <joint_name>zephyr_delta_wing::flap_left_joint</joint_name>
          <joint_control_pid>
            <p>10.0</p>
            <i>0</i>
            <d>0</d>
            <iMax>0</iMax>
            <iMin>0</iMin>
            <cmdMax>20</cmdMax>
            <cmdMin>-20</cmdMin>
          </joint_control_pid>
        </channel>
        <channel name="rotor7">
          <input_index>6</input_index>
          <input_offset>0</input_offset>
          <!-- joint limits [-0.524, 0.524] -->
          <input_scaling>0.524</input_scaling>
          <zero_position_disarmed>0</zero_position_disarmed>
          <zero_position_armed>0</zero_position_armed>
          <joint_control_type>position</joint_control_type>
          <joint_name>zephyr_delta_wing::flap_right_joint</joint_name>
          <joint_control_pid>
            <p>10.0</p>
            <i>0</i>
            <d>0</d>
            <iMax>0</iMax>
            <iMin>0</iMin>
            <cmdMax>20</cmdMax>
            <cmdMin>-20</cmdMin>
          </joint_control_pid>
        </channel>
        <channel name="rotor8">
          <input_index>7</input_index>
          <input_offset>0</input_offset>
          <input_scaling>0.524</input_scaling>
          <zero_position_disarmed>0</zero_position_disarmed>
          <zero_position_armed>0</zero_position_armed>
          <joint_control_type>position</joint_control_type>
        </channel>
      </control_channels>
    </plugin>
  </gazebo>
  <!-- IMU link -->
  <link name="/imu_link">
    <inertial>
      <inertia ixx="0.00001" ixy="0.0" ixz="0.0" iyy="0.00001" iyz="0.0" izz="0.00001"/>
      <mass value="0.015"/>
      <!-- [kg] -->
      <origin rpy="0 0 0" xyz="0 0 0"/>
    </inertial>
  </link>
  <!-- IMU joint -->
  <joint name="/imu_joint" type="revolute">
    <origin rpy="0 0 0" xyz="0 0 0"/>
    <parent link="base_link"/>
    <child link="/imu_link"/>
    <limit effort="0" lower="0" upper="0" velocity="0"/>
  </joint>
  <gazebo>
    <plugin filename="librotors_gazebo_imu_plugin.so" name="rotors_gazebo_imu_plugin">
      <!-- A good description of the IMU parameters can be found in the kalibr documentation:
           https://github.com/ethz-asl/kalibr/wiki/IMU-Noise-Model-and-Intrinsics -->
      <robotNamespace></robotNamespace>
      <!-- (string, required): ros namespace in which the messages are published -->
      <linkName>/imu_link</linkName>
      <!-- (string, required): name of the body which holds the IMU sensor -->
      <imuTopic>/imu</imuTopic>
      <!-- (string): name of the sensor output topic and prefix of service names (defaults to imu) -->
      <gyroscopeNoiseDensity>0.0003394</gyroscopeNoiseDensity>
      <!-- Gyroscope noise density (two-sided spectrum) [rad/s/sqrt(Hz)] -->
      <gyroscopeRandomWalk>3.8785e-05</gyroscopeRandomWalk>
      <!-- Gyroscope bias random walk [rad/s/s/sqrt(Hz)] -->
      <gyroscopeBiasCorrelationTime>1000.0</gyroscopeBiasCorrelationTime>
      <!-- Gyroscope bias correlation time constant [s] -->
      <gyroscopeTurnOnBiasSigma>0.0087</gyroscopeTurnOnBiasSigma>
      <!-- Gyroscope turn on bias standard deviation [rad/s] -->
      <accelerometerNoiseDensity>0.004</accelerometerNoiseDensity>
      <!-- Accelerometer noise density (two-sided spectrum) [m/s^2/sqrt(Hz)] -->
      <accelerometerRandomWalk>0.006</accelerometerRandomWalk>
      <!-- Accelerometer bias random walk. [m/s^2/s/sqrt(Hz)] -->
      <accelerometerBiasCorrelationTime>300.0</accelerometerBiasCorrelationTime>
      <!-- Accelerometer bias correlation time constant [s] -->
      <accelerometerTurnOnBiasSigma>0.196</accelerometerTurnOnBiasSigma>
      <!-- Accelerometer turn on bias standard deviation [m/s^2] -->
    </plugin>
  </gazebo>
  <joint name="camera_joint" type="fixed">
    <origin rpy="0 0 0" xyz="0.1475 0.0 0.0"/>
    <parent link="base_link"/>
    <child link="camera_link"/>
  </joint>
  <link name="camera_link">
    <inertial>
      <mass value="0"/>
      <origin rpy="0 0 0" xyz="0 0 0"/>
      <inertia ixx="5.8083e-4" ixy="0" ixz="0" iyy="3.0833e-5" iyz="0" izz="5.9083e-4"/>
    </inertial>
    <visual>
      <origin rpy="0 0 0" xyz="0 0 0"/>
      <geometry>
        <mesh filename="/home/oli/src/Firmware/Tools/sitl_gazebo/models/camera/meshes/asus_camera_simple.dae"/>
      </geometry>
    </visual>
    <!--        
       <collision>
          <origin xyz="0 0 0" rpy="0 0 0" />
          <geometry>
            <box size="0.035 0.185 0.025"/>
          </geometry>
        </collision>
        -->
    <collision>
      <origin rpy="0 0 0" xyz="0 0 0"/>
      <geometry>
        <mesh filename="/home/oli/src/Firmware/Tools/sitl_gazebo/models/camera/meshes/asus_camera_simple.dae"/>
      </geometry>
    </collision>
  </link>
  <joint name="camera_depth_joint" type="fixed">
    <origin rpy="0 0 0" xyz="0.0 0.049 0.0"/>
    <parent link="camera_link"/>
    <child link="camera_depth_frame"/>
  </joint>
  <link name="camera_depth_frame"/>
  <joint name="camera_depth_optical_joint" type="fixed">
    <origin rpy="-1.57079632679 0.0 -1.57079632679" xyz="0 0 0"/>
    <parent link="camera_depth_frame"/>
    <child link="camera_depth_optical_frame"/>
  </joint>
  <link name="camera_depth_optical_frame"/>
  <joint name="camera_rgb_joint" type="fixed">
    <origin rpy="0 0 0" xyz="0.0 0.022 0.0"/>
    <parent link="camera_link"/>
    <child link="camera_rgb_frame"/>
  </joint>
  <link name="camera_rgb_frame"/>
  <joint name="camera_rgb_optical_joint" type="fixed">
    <origin rpy="-1.57079632679 0.0 -1.57079632679" xyz="0 0 0"/>
    <parent link="camera_rgb_frame"/>
    <child link="camera_rgb_optical_frame"/>
  </joint>
  <link name="camera_rgb_optical_frame"/>
  <!-- ASUS Xtion PRO camera for simulation -->
  <gazebo reference="camera_depth_frame">
    <sensor name="camera" type="depth">
      <update_rate>30</update_rate>
      <camera>
        <horizontal_fov>1.91986217719</horizontal_fov>
        <image>
          <format>R8G8B8</format>
          <width>640</width>
          <height>480</height>
        </image>
        <clip>
          <near>0.7</near>
          <far>15</far>
        </clip>
      </camera>
      <plugin filename="libgazebo_ros_openni_kinect.so" name="camera_camera_controller">
        <imageTopicName>camera/rgb/image_raw</imageTopicName>
        <cameraInfoTopicName>camera/rgb/camera_info</cameraInfoTopicName>
        <depthImageTopicName>camera/depth/image_raw</depthImageTopicName>
        <depthImageCameraInfoTopicName>camera/depth/camera_info</depthImageCameraInfoTopicName>
        <pointCloudTopicName>camera/depth/points</pointCloudTopicName>
        <frameName>camera_depth_optical_frame</frameName>
      </plugin>
    </sensor>
  </gazebo>
  <joint name="tag_joint" type="fixed">
    <origin rpy="0 0 0" xyz="0.7 0.0 0.0"/>
    <parent link="base_link"/>
    <child link="tag_link"/>
  </joint>
  <link name="tag_link">
    <inertial>
      <origin xyz="0 0 0"/>
      <mass value="0.01"/>
      <inertia ixx="0.00000001" ixy="0.0" ixz="0.0" iyy="0.00000001" iyz="0.0" izz="0.00000001"/>
    </inertial>
    <visual>
      <origin rpy="0 -1.57079632679 0" xyz="0 0 0"/>
      <geometry>
        <mesh filename="/home/oli/src/Firmware/Tools/sitl_gazebo/models/tag/meshes/tag.dae"/>
      </geometry>
    </visual>
    <collision>
      <origin rpy="0 0 0" xyz="0 0 0"/>
      <geometry>
        <mesh filename="/home/oli/src/Firmware/Tools/sitl_gazebo/models/tag/meshes/tag.dae"/>
      </geometry>
    </collision>
  </link>
  <joint name="tag_background_joint" type="fixed">
    <origin rpy="0 0 0" xyz="0 0 -0.001"/>
    <parent link="tag_link"/>
    <child link="tag_background_link"/>
  </joint>
  <link name="tag_background_link">
    <inertial>
      <origin xyz="0 0 0"/>
      <mass value="0.01"/>
      <inertia ixx="0.00000001" ixy="0.0" ixz="0.0" iyy="0.00000001" iyz="0.0" izz="0.00000001"/>
    </inertial>
    <visual>
      <origin rpy="0 0 0" xyz="0 0 0"/>
      <geometry>
        <box size="0.1 0.1 0.001"/>
      </geometry>
    </visual>
    <collision>
      <origin rpy="0 0 0" xyz="0 0 0"/>
      <geometry>
        <box size="0.1 0.1 0.0001"/>
      </geometry>
    </collision>
  </link>
  <gazebo reference="tag_link">
    <!--
      <material>artag/${name}</material>
      <turnGravityOff>false</turnGravityOff>
      <static>false</static>
      -->
  </gazebo>
  <gazebo reference="tag_background_link">
    <material>Gazebo/White</material>
    <!--
      <turnGravityOff>false</turnGravityOff>
      <static>false</static>
      -->
  </gazebo>
</robot>



<!-- Inserisco iRobot -->

<!-- =================================================================================== -->
<!-- |    This document was autogenerated by xacro from iRobot.urdf.xacro              | -->
<!-- |    EDITING THIS FILE BY HAND IS NOT RECOMMENDED                                 | -->
<!-- =================================================================================== -->
<robot name="iRobot" xmlns:xacro="http://www.ros.org/wiki/xacro">
  <!-- MODELS -->
  <material name="iRobot/Green">
    <color rgba="0.0 1.0 0.0 1.0"/>
  </material>
  <material name="iRobot/Yellow">
    <color rgba="1.0 1.0 0.0 1.0"/>
  </material>
  <material name="iRobot/LightYellow">
    <color rgba="1.0 1.0 0.6 1.0"/>
  </material>
  <material name="iRobot/Blue">
    <color rgba="0.0 0.0 1.0 1.0"/>
  </material>
  <material name="iRobot/LightBlue">
    <color rgba="0.6 0.79 1.0 1.0"/>
  </material>
  <material name="iRobot/DarkGrey">
    <color rgba="0.31 0.31 0.31 1.0"/>
  </material>
  <material name="iRobot/LightGrey">
    <color rgba="0.83 0.83 0.83 1.0"/>
  </material>
  <material name="iRobot/MediumGrey">
    <color rgba="0.5 0.5 0.5 1.0"/>
  </material>
  <material name="iRobot/Black">
    <color rgba="0.0 0.0 0.0 1.0"/>
  </material>
  <material name="iRobot/Red">
    <color rgba="1.0 0.0 0.0 1.0"/>
  </material>
  <material name="iRobot/Orange">
    <color rgba="1.0 0.65 0.0 1.0"/>
  </material>
  <link name="base_link">
    <inertial>
      <origin rpy="0 0 0" xyz="0 0 0"/>
      <mass value="0"/>
      <inertia ixx="0.0" ixy="0.0" ixz="0.0" iyy="0.0" iyz="0.0" izz="0.0"/>
    </inertial>
  </link>
  <joint name="base_joint" type="fixed">
    <origin rpy="0 0 0" xyz="0 0 0"/>
    <parent link="base_link"/>
    <child link="chassis"/>
  </joint>
  <link name="chassis">
    <inertial>
      <origin rpy="0 0 0" xyz="0 0 0"/>
      <mass value="10"/>
      <inertia ixx="0.425" ixy="0.0" ixz="0.0" iyy="0.425" iyz="0.0" izz="0.85"/>
    </inertial>
    <visual>
      <origin rpy="0 0 0" xyz="0 0 0"/>
      <geometry>
        <cylinder length="0.08" radius="0.17"/>
      </geometry>
      <material name="iRobot/LightGrey"/>
    </visual>
    <collision>
      <origin rpy="0 0 0" xyz="0 0 0"/>
      <geometry>
        <cylinder length="0.08" radius="0.17"/>
      </geometry>
    </collision>
  </link>
  <joint name="left_axis_base_joint" type="fixed">
    <origin rpy="0 0 0" xyz="0 0.14 -0.02"/>
    <parent link="chassis"/>
    <child link="left_axis"/>
  </joint>
  <link name="left_axis">
    <inertial>
      <origin rpy="-1.57079632679 0 0" xyz="0 0 0"/>
      <mass value="0.001"/>
      <inertia ixx="6.25e-07" ixy="0.0" ixz="0.0" iyy="6.25e-07" iyz="0.0" izz="2.08333333333e-07"/>
    </inertial>
    <visual>
      <origin rpy="-1.57079632679 0 0" xyz="0 0 0"/>
      <geometry>
        <cylinder length="0.02" radius="0.0025"/>
      </geometry>
      <material name="iRobot/MediumGray"/>
    </visual>
    <collision>
      <origin rpy="-1.57079632679 0 0" xyz="0 0 0"/>
      <geometry>
        <cylinder length="0.02" radius="0.0025"/>
      </geometry>
    </collision>
  </link>
  <gazebo reference="left_axis_axis">
    <gravity>true</gravity>
    <material>Gazebo/Red</material>
    <mu1>0.8</mu1>
    <mu2>0.8</mu2>
  </gazebo>
  <joint name="left_wheel_rot_joint" type="continuous">
    <origin rpy="0 0 0" xyz="0 0 0"/>
    <axis xyz="0 1 0"/>
    <limit effort="100" velocity="100"/>
    <joint_properties damping="0.0" friction="0.0"/>
    <parent link="left_axis"/>
    <child link="left_wheel_link"/>
  </joint>
  <link name="left_wheel_link">
    <inertial>
      <origin rpy="-1.57079632679 0 0" xyz="0 0.01 0"/>
      <mass value="0.5"/>
      <inertia ixx="0.00375" ixy="0.0" ixz="0.0" iyy="0.00375" iyz="0.0" izz="0.00125"/>
    </inertial>
    <visual>
      <origin rpy="-1.57079632679 0 0" xyz="0 0 0"/>
      <geometry>
        <cylinder length="0.02" radius="0.03"/>
      </geometry>
      <material name="iRobot/Black"/>
    </visual>
    <collision>
      <origin rpy="-1.57079632679 0 0" xyz="0 0 0"/>
      <geometry>
        <cylinder length="0.02" radius="0.03"/>
      </geometry>
    </collision>
  </link>
  <gazebo reference="left_wheel_link">
    <gravity>true</gravity>
    <material>Gazebo/Grey</material>
    <mu1>50</mu1>
    <mu2>10</mu2>
    <kp>10000000</kp>
    <kd>1</kd>
    <fdir1>1 0 0</fdir1>
    <minDepth>0.0001</minDepth>
    <maxContacts>1</maxContacts>
  </gazebo>
  <joint name="right_axis_base_joint" type="fixed">
    <origin rpy="0 0 0" xyz="0 -0.14 -0.02"/>
    <parent link="chassis"/>
    <child link="right_axis"/>
  </joint>
  <link name="right_axis">
    <inertial>
      <origin rpy="-1.57079632679 0 0" xyz="0 0 0"/>
      <mass value="0.001"/>
      <inertia ixx="6.25e-07" ixy="0.0" ixz="0.0" iyy="6.25e-07" iyz="0.0" izz="2.08333333333e-07"/>
    </inertial>
    <visual>
      <origin rpy="-1.57079632679 0 0" xyz="0 0 0"/>
      <geometry>
        <cylinder length="0.02" radius="0.0025"/>
      </geometry>
      <material name="iRobot/MediumGray"/>
    </visual>
    <collision>
      <origin rpy="-1.57079632679 0 0" xyz="0 0 0"/>
      <geometry>
        <cylinder length="0.02" radius="0.0025"/>
      </geometry>
    </collision>
  </link>
  <gazebo reference="right_axis_axis">
    <gravity>true</gravity>
    <material>Gazebo/Red</material>
    <mu1>0.8</mu1>
    <mu2>0.8</mu2>
  </gazebo>
  <joint name="right_wheel_rot_joint" type="continuous">
    <origin rpy="0 0 0" xyz="0 0 0"/>
    <axis xyz="0 1 0"/>
    <limit effort="100" velocity="100"/>
    <joint_properties damping="0.0" friction="0.0"/>
    <parent link="right_axis"/>
    <child link="right_wheel_link"/>
  </joint>
  <link name="right_wheel_link">
    <inertial>
      <origin rpy="-1.57079632679 0 0" xyz="0 0.01 0"/>
      <mass value="0.5"/>
      <inertia ixx="0.00375" ixy="0.0" ixz="0.0" iyy="0.00375" iyz="0.0" izz="0.00125"/>
    </inertial>
    <visual>
      <origin rpy="-1.57079632679 0 0" xyz="0 0 0"/>
      <geometry>
        <cylinder length="0.02" radius="0.03"/>
      </geometry>
      <material name="iRobot/Black"/>
    </visual>
    <collision>
      <origin rpy="-1.57079632679 0 0" xyz="0 0 0"/>
      <geometry>
        <cylinder length="0.02" radius="0.03"/>
      </geometry>
    </collision>
  </link>
  <gazebo reference="right_wheel_link">
    <gravity>true</gravity>
    <material>Gazebo/Grey</material>
    <mu1>50</mu1>
    <mu2>10</mu2>
    <kp>10000000</kp>
    <kd>1</kd>
    <fdir1>1 0 0</fdir1>
    <minDepth>0.0001</minDepth>
    <maxContacts>1</maxContacts>
  </gazebo>
  <joint name="sphere_joint1" type="revolute">
    <origin rpy="0 0 0" xyz="0.14 0 -0.04"/>
    <axis xyz="0 0 1"/>
    <limit effort="100" lower="0" upper="0" velocity="100"/>
    <parent link="chassis"/>
    <child link="sphere1"/>
  </joint>
  <link name="sphere1">
    <inertial>
      <origin rpy="0 0 0" xyz="0 0 0"/>
      <mass value="0.3"/>
      <inertia ixx="0.0012" ixy="0.0" ixz="0.0" iyy="0.0012" iyz="0.0" izz="0.0012"/>
    </inertial>
    <visual>
      <origin rpy="0 0 0" xyz="0 0 0"/>
      <geometry>
        <sphere radius="0.01"/>
      </geometry>
      <material name="iRobot/Black"/>
    </visual>
    <collision>
      <origin rpy="0 0 0" xyz="0 0 0"/>
      <geometry>
        <sphere radius="0.01"/>
      </geometry>
    </collision>
  </link>
  <joint name="sphere_joint2" type="revolute">
    <origin rpy="0 0 0" xyz="-0.14 0 -0.04"/>
    <axis xyz="0 0 1"/>
    <limit effort="100" lower="0" upper="0" velocity="100"/>
    <parent link="chassis"/>
    <child link="sphere2"/>
  </joint>
  <link name="sphere2">
    <inertial>
      <origin rpy="0 0 0" xyz="0 0 0"/>
      <mass value="0.3"/>
      <inertia ixx="0.0012" ixy="0.0" ixz="0.0" iyy="0.0012" iyz="0.0" izz="0.0012"/>
    </inertial>
    <visual>
      <origin rpy="0 0 0" xyz="0 0 0"/>
      <geometry>
        <sphere radius="0.01"/>
      </geometry>
      <material name="iRobot/Black"/>
    </visual>
    <collision>
      <origin rpy="0 0 0" xyz="0 0 0"/>
      <geometry>
        <sphere radius="0.01"/>
      </geometry>
    </collision>
  </link>
  <!-- Laser link and plugin -->
  <joint name="hokuyo_laser_joint" type="fixed">
    <axis xyz="0 0 1"/>
    <origin rpy="0 0 0" xyz="0 0 0.06"/>
    <parent link="base_link"/>
    <child link="hokuyo_laser_link"/>
  </joint>
  <link name="hokuyo_laser_link">
    <collision>
      <origin rpy="0 0 0" xyz="0 0 0"/>
      <geometry>
        <cylinder length="0.04" radius="0.045"/>
      </geometry>
    </collision>
    <visual>
      <origin rpy="0 0 0" xyz="0 0 0"/>
      <geometry>
        <cylinder length="0.04" radius="0.045"/>
      </geometry>
      <material name="iRobot/LightBlue"/>
    </visual>
    <inertial>
      <mass value="1e-5"/>
      <origin rpy="0 0 0" xyz="0 0 0"/>
      <inertia ixx="1e-6" ixy="0" ixz="0" iyy="1e-6" iyz="0" izz="1e-6"/>
    </inertial>
  </link>
  <gazebo reference="hokuyo_laser_link">
    <gravity>true</gravity>
    <sensor name="head_hokuyo_sensor" type="ray">
      <pose>0 0 0 0 0 0</pose>
      <visualize>true</visualize>
      <update_rate>40</update_rate>
      <ray>
        <scan>
          <horizontal>
            <samples>360</samples>
            <resolution>1</resolution>
            <min_angle>-3.14159</min_angle>
            <max_angle>3.14159</max_angle>
          </horizontal>
        </scan>
        <range>
          <min>0.2</min>
          <max>40</max>
          <resolution>0.025</resolution>
        </range>
        <noise>
          <type>gaussian</type>
          <mean>0.0</mean>
          <stddev>0.0</stddev>
        </noise>
      </ray>
      <plugin filename="libgazebo_ros_laser.so" name="gazebo_ros_head_hokuyo_controller">
        <robotNamespace/>
        <topicName>laser_scan</topicName>
        <frameName>hokuyo_laser_link</frameName>
      </plugin>
    </sensor>
  </gazebo>
  <!--Imu link and plugin-->
  <joint name="imu_sensor_joint" type="fixed">
    <axis xyz="0 0 1"/>
    <origin rpy="0 0 0" xyz="-0.1 0 0.05"/>
    <parent link="base_link"/>
    <child link="imu_sensor_link"/>
  </joint>
  <link name="imu_sensor_link">
    <collision>
      <origin rpy="0 0 0" xyz="0 0 0"/>
      <geometry>
        <box size="0.02 0.02 0.02"/>
      </geometry>
    </collision>
    <visual>
      <origin rpy="0 0 0" xyz="0 0 0"/>
      <geometry>
        <box size="0.02 0.02 0.02"/>
      </geometry>
      <material name="iRobot/Red"/>
    </visual>
    <inertial>
      <mass value="0.001"/>
      <origin rpy="0 0 0" xyz="0 0 0"/>
      <inertia ixx="0.00000015" ixy="0" ixz="0" iyy="0.00000015" iyz="0" izz="0.00000015"/>
    </inertial>
  </link>
  <gazebo reference="imu_sensor_link">
    <gravity>true</gravity>
    <sensor name="imu_sensor" type="imu">
      <always_on>1</always_on>
      <update_rate>1000</update_rate>
      <visualize>1</visualize>
      <topic>__default_topic__</topic>
      <plugin filename="libgazebo_ros_imu_sensor.so" name="imu_plugin">
        <topicName>imu_data</topicName>
        <bodyName>imu_sensor_link</bodyName>
        <updateRateHZ>10.0</updateRateHZ>
        <gaussianNoise>0.0</gaussianNoise>
        <xyzOffset>0 0 0</xyzOffset>
        <rpyOffset>0 0 0</rpyOffset>
      </plugin>
      <pose>0 0 0 0 0 0</pose>
    </sensor>
  </gazebo>
  <!--Camera link and plugin-->
  <joint name="camera_sensor_joint" type="fixed">
    <axis xyz="0 1 0"/>
    <origin rpy="0 0 0" xyz="0 0 0.1"/>
    <parent link="base_link"/>
    <child link="camera_link"/>
  </joint>
  <link name="camera_link">
    <collision>
      <origin rpy="0 0 0" xyz="0 0 0"/>
      <geometry>
        <box size="0.02 0.08 0.05"/>
      </geometry>
    </collision>
    <visual>
      <origin rpy="0 0 0" xyz="0 0 0"/>
      <geometry>
        <box size="0.02 0.08 0.05"/>
      </geometry>
      <material name="iRobot/Green"/>
    </visual>
    <inertial>
      <mass value="0.0001"/>
      <origin rpy="0 0 3.14159265359" xyz="0 0 0"/>
      <inertia ixx="0.0000001" ixy="0" ixz="0" iyy="0.0000001" iyz="0" izz="0.0000001"/>
    </inertial>
  </link>
  <gazebo reference="camera_link">
    <sensor name="camera" type="camera">
      <update_rate>30.0</update_rate>
      <camera name="head">
        <horizontal_fov>1.3962634</horizontal_fov>
        <image>
          <width>800</width>
          <height>600</height>
          <format>R8G8B8</format>
        </image>
        <clip>
          <near>0.02</near>
          <far>300</far>
        </clip>
        <noise>
          <type>gaussian</type>
          <mean>0.0</mean>
          <stddev>0.007</stddev>
        </noise>
      </camera>
      <plugin filename="libgazebo_ros_camera.so" name="camera_controller">
        <alwaysOn>true</alwaysOn>
        <updateRate>0.0</updateRate>
        <cameraName>iRobot/camera</cameraName>
        <imageTopicName>image_raw</imageTopicName>
        <cameraInfoTopicName>camera_info</cameraInfoTopicName>
        <frameName>camera_link</frameName>
        <hackBaseline>0.07</hackBaseline>
        <distortionK1>0.0</distortionK1>
        <distortionK2>0.0</distortionK2>
        <distortionK3>0.0</distortionK3>
        <distortionT1>0.0</distortionT1>
        <distortionT2>0.0</distortionT2>
      </plugin>
    </sensor>
  </gazebo>
  <!--    <xacro:model_shelf name="first_shelf" 
                       parent="chassis"
                       height="0.15">
    </xacro:model_shelf>-->
  <!--    <xacro:model_shelf name="second_shelf" 
                       parent="first_shelf"
                       height="0.25">
    </xacro:model_shelf>
    -->
  <gazebo reference="base_link">
    </gazebo>
  <gazebo reference="ground">
    </gazebo>
  <gazebo reference="sphere1">
    <gravity>true</gravity>
    <material>Gazebo/Grey</material>
    <mu1>0</mu1>
    <mu2>0</mu2>
    <kp>10000000</kp>
    <kd>1</kd>
    <fdir1>1 0 0</fdir1>
    <minDepth>0.0001</minDepth>
    <maxContacts>1</maxContacts>
  </gazebo>
  <gazebo reference="sphere2">
    <gravity>true</gravity>
    <material>Gazebo/Grey</material>
    <mu1>0</mu1>
    <mu2>0</mu2>
    <kp>10000000</kp>
    <kd>1</kd>
    <fdir1>1 0 0</fdir1>
    <minDepth>0.0001</minDepth>
    <maxContacts>1</maxContacts>
  </gazebo>
  <gazebo reference="chassis">
    <gravity>true</gravity>
    <material>Gazebo/Yellow</material>
  </gazebo>
  <gazebo>
    <static>false</static>
    <plugin filename="libgazebo_ros_diff_drive.so" name="differential_drive_controller">
      <rosDebugLevel>Debug</rosDebugLevel>
      <publishWheelTF>false</publishWheelTF>
      <publishWheelJointState>true</publishWheelJointState>
      <alwaysOn>true</alwaysOn>
      <leftJoint>left_wheel_rot_joint</leftJoint>
      <rightJoint>right_wheel_rot_joint</rightJoint>
      <wheelSeparation>0.28</wheelSeparation>
      <wheelDiameter>0.06</wheelDiameter>
      <torque>20</torque>
      <wheelAcceleration>1.8</wheelAcceleration>
      <commandTopic>cmd_vel</commandTopic>
      <odometryTopic>odom</odometryTopic>
      <odometryFrame>odom</odometryFrame>
      <odometrySource>encoder</odometrySource>
      <robotBaseFrame>base_link</robotBaseFrame>
      <updateRate>10.0</updateRate>
    </plugin>
    <plugin filename="libgazebo_ros_joint_state_publisher.so" name="joint_state_publisher">
      <jointName>left_wheel_rot_joint, right_wheel_rot_joint</jointName>
      <updateRate>10.0</updateRate>
      <alwaysOn>true</alwaysOn>
    </plugin>
    <plugin filename="libgazebo_ros_imu.so" name="imu_plugin">
      <bodyName>base_link</bodyName>
      <updateRate>100.0</updateRate>
      <topicName>imu_data</topicName>
      <serviceName>imu_service</serviceName>
      <gaussianNoise>0.1</gaussianNoise>
      <xyzOffset>0 0 0</xyzOffset>
      <rpyOffset>0 0 0</rpyOffset>
    </plugin>
  </gazebo>
</robot>





